2024-02-09T00:00:09 {"cpu": 2.36376953125, "cpu_total": 12, "cpu_usage": 0.19698079427083334, "memory": 1223.0, "memory_total": 8864.0, "memory_usage": 0.13797382671480143, "pipeline_run_id": 2, "pipeline_schedule_id": 1, "pipeline_uuid": "green_taxi_etl", "hostname": "2156a6b6cd4d", "level": "INFO", "message": "Pipeline green_taxi_etl for run 2 in schedule 1 is alive.", "timestamp": 1707436809.603832, "uuid": "e53f899a53d54fe68825367cf498a879"}
2024-02-09T00:00:09 {"block_run_id": 8, "block_uuid": "load_api_data", "pipeline_run_id": 2, "pipeline_schedule_id": 1, "pipeline_uuid": "green_taxi_etl", "hostname": "2156a6b6cd4d", "level": "INFO", "message": "Execute PipelineRun 2, BlockRun 8: pipeline green_taxi_etl block load_api_data", "timestamp": 1707436809.710182, "uuid": "558d9902fee94d5682af55d471458ce7"}
2024-02-09T00:00:09 {"cpu": 2.36376953125, "cpu_total": 12, "cpu_usage": 0.19698079427083334, "memory": 1270.0, "memory_total": 8864.0, "memory_usage": 0.14327617328519857, "pipeline_run_id": 2, "pipeline_schedule_id": 1, "pipeline_uuid": "green_taxi_etl", "hostname": "2156a6b6cd4d", "level": "INFO", "message": "Pipeline green_taxi_etl for run 2 in schedule 1 is alive.", "timestamp": 1707436809.72622, "uuid": "7e8b4f52f1af457ba65117d46b173ca5"}
2024-02-09T00:00:10 {"block_run_id": 11, "block_uuid": "load_taxi_data", "pipeline_run_id": 2, "pipeline_schedule_id": 1, "pipeline_uuid": "green_taxi_etl", "hostname": "2156a6b6cd4d", "level": "INFO", "message": "Execute PipelineRun 2, BlockRun 11: pipeline green_taxi_etl block load_taxi_data", "timestamp": 1707436810.734069, "uuid": "0c39b736a2c24cd29bdb8086af1c0fb1"}
2024-02-09T00:00:10 {"block_run_id": 12, "block_uuid": "test_gcs", "pipeline_run_id": 2, "pipeline_schedule_id": 1, "pipeline_uuid": "green_taxi_etl", "hostname": "2156a6b6cd4d", "level": "INFO", "message": "Execute PipelineRun 2, BlockRun 12: pipeline green_taxi_etl block test_gcs", "timestamp": 1707436810.734151, "uuid": "fa57f3e5c2b748e6ac6734c84a1616b8"}
2024-02-09T00:00:11 {"block_run_id": 12, "block_uuid": "test_gcs", "pipeline_run_id": 2, "pipeline_schedule_id": 1, "pipeline_uuid": "green_taxi_etl", "hostname": "2156a6b6cd4d", "level": "INFO", "message": "BlockRun 12 (block_uuid: test_gcs) completes.", "timestamp": 1707436811.364012, "uuid": "ba7f6d6936654904a1f55e64b17271e8"}
2024-02-09T00:00:11 {"block_run_id": 8, "block_uuid": "load_api_data", "pipeline_run_id": 2, "pipeline_schedule_id": 1, "pipeline_uuid": "green_taxi_etl", "hostname": "2156a6b6cd4d", "level": "INFO", "message": "BlockRun 8 (block_uuid: load_api_data) completes.", "timestamp": 1707436811.775353, "uuid": "b0de0cf73cdd4299bb82a64c72c8dd32"}
2024-02-09T00:00:13 {"block_run_id": 11, "block_uuid": "load_taxi_data", "pipeline_run_id": 2, "pipeline_schedule_id": 1, "pipeline_uuid": "green_taxi_etl", "hostname": "2156a6b6cd4d", "level": "INFO", "message": "BlockRun 11 (block_uuid: load_taxi_data) completes.", "timestamp": 1707436813.875323, "uuid": "8a0bfc968b484fff8fd974518c3f8056"}
2024-02-09T00:00:19 {"cpu": 2.35400390625, "cpu_total": 12, "cpu_usage": 0.1961669921875, "memory": 1229.0, "memory_total": 8864.0, "memory_usage": 0.13865072202166065, "pipeline_run_id": 2, "pipeline_schedule_id": 1, "pipeline_uuid": "green_taxi_etl", "hostname": "2156a6b6cd4d", "level": "INFO", "message": "Pipeline green_taxi_etl for run 2 in schedule 1 is alive.", "timestamp": 1707436819.840623, "uuid": "339a707ab07445b4afac22d6f91f7c78"}
2024-02-09T00:00:19 {"block_run_id": 9, "block_uuid": "transform_taxi_data", "pipeline_run_id": 2, "pipeline_schedule_id": 1, "pipeline_uuid": "green_taxi_etl", "hostname": "2156a6b6cd4d", "level": "INFO", "message": "Execute PipelineRun 2, BlockRun 9: pipeline green_taxi_etl block transform_taxi_data", "timestamp": 1707436819.910175, "uuid": "5334bc3e246c4bd2af016060a903b399"}
2024-02-09T00:00:20 {"block_run_id": 9, "block_uuid": "transform_taxi_data", "pipeline_run_id": 2, "pipeline_schedule_id": 1, "pipeline_uuid": "green_taxi_etl", "hostname": "2156a6b6cd4d", "level": "INFO", "message": "BlockRun 9 (block_uuid: transform_taxi_data) completes.", "timestamp": 1707436820.134125, "uuid": "d20f82a2aacf4fa2bcb661207da17731"}
2024-02-09T00:00:29 {"cpu": 2.35595703125, "cpu_total": 12, "cpu_usage": 0.19632975260416666, "memory": 1224.0, "memory_total": 8864.0, "memory_usage": 0.13808664259927797, "pipeline_run_id": 2, "pipeline_schedule_id": 1, "pipeline_uuid": "green_taxi_etl", "hostname": "2156a6b6cd4d", "level": "INFO", "message": "Pipeline green_taxi_etl for run 2 in schedule 1 is alive.", "timestamp": 1707436829.974009, "uuid": "035120a3a99b4630b0053f28ee6c3b65"}
2024-02-09T00:00:30 {"block_run_id": 10, "block_uuid": "taxi_data_to_postgres", "pipeline_run_id": 2, "pipeline_schedule_id": 1, "pipeline_uuid": "green_taxi_etl", "hostname": "2156a6b6cd4d", "level": "INFO", "message": "Execute PipelineRun 2, BlockRun 10: pipeline green_taxi_etl block taxi_data_to_postgres", "timestamp": 1707436830.045179, "uuid": "b59e95d6d4b541709190bd5bc7899df3"}
2024-02-09T00:00:31 {"block_run_id": 13, "block_uuid": "taxi_to_gcs_parquet", "pipeline_run_id": 2, "pipeline_schedule_id": 1, "pipeline_uuid": "green_taxi_etl", "hostname": "2156a6b6cd4d", "level": "INFO", "message": "Execute PipelineRun 2, BlockRun 13: pipeline green_taxi_etl block taxi_to_gcs_parquet", "timestamp": 1707436831.098739, "uuid": "8c1503b9d8704f4581eae114612c0125"}
2024-02-09T00:00:31 {"block_run_id": 14, "block_uuid": "taxi_to_gcs_partitioned_parquet", "pipeline_run_id": 2, "pipeline_schedule_id": 1, "pipeline_uuid": "green_taxi_etl", "hostname": "2156a6b6cd4d", "level": "INFO", "message": "Execute PipelineRun 2, BlockRun 14: pipeline green_taxi_etl block taxi_to_gcs_partitioned_parquet", "timestamp": 1707436831.101605, "uuid": "0a6e04f7d3ea4c19ad07f550372c1975"}
2024-02-09T00:00:31 {"block_run_id": 10, "block_uuid": "taxi_data_to_postgres", "pipeline_run_id": 2, "pipeline_schedule_id": 1, "pipeline_uuid": "green_taxi_etl", "hostname": "2156a6b6cd4d", "level": "EXCEPTION", "message": "BlockRun 10 (block_uuid: taxi_data_to_postgres) failed.", "timestamp": 1707436831.51967, "uuid": "cc3f0c398a934cb48f0c59506dadf08a", "error": ["Traceback (most recent call last):\n  File \"/usr/local/lib/python3.10/site-packages/mage_ai/io/base.py\", line 347, in conn\n    return self._ctx\nAttributeError: 'Postgres' object has no attribute '_ctx'\n\nDuring handling of the above exception, another exception occurred:\n\nTraceback (most recent call last):\n  File \"/usr/local/lib/python3.10/site-packages/mage_ai/data_preparation/executors/block_executor.py\", line 613, in execute\n    result = __execute_with_retry()\n  File \"/usr/local/lib/python3.10/site-packages/mage_ai/shared/retry.py\", line 54, in retry_func\n    raise e\n  File \"/usr/local/lib/python3.10/site-packages/mage_ai/shared/retry.py\", line 38, in retry_func\n    return func(*args, **kwargs)\n  File \"/usr/local/lib/python3.10/site-packages/mage_ai/data_preparation/executors/block_executor.py\", line 588, in __execute_with_retry\n    return self._execute(\n  File \"/usr/local/lib/python3.10/site-packages/mage_ai/data_preparation/executors/block_executor.py\", line 1077, in _execute\n    result = self.block.execute_sync(\n  File \"/usr/local/lib/python3.10/site-packages/mage_ai/data_preparation/models/block/__init__.py\", line 1312, in execute_sync\n    raise err\n  File \"/usr/local/lib/python3.10/site-packages/mage_ai/data_preparation/models/block/__init__.py\", line 1221, in execute_sync\n    output = self.execute_block(\n  File \"/usr/local/lib/python3.10/site-packages/mage_ai/data_preparation/models/block/__init__.py\", line 1527, in execute_block\n    outputs = self._execute_block(\n  File \"/usr/local/lib/python3.10/site-packages/mage_ai/data_preparation/models/block/__init__.py\", line 1683, in _execute_block\n    outputs = self.execute_block_function(\n  File \"/usr/local/lib/python3.10/site-packages/mage_ai/data_preparation/models/block/__init__.py\", line 1722, in execute_block_function\n    output = block_function_updated(*input_vars, **global_vars)\n  File \"<string>\", line 25, in export_data_to_postgres\n  File \"/usr/local/lib/python3.10/site-packages/mage_ai/io/sql.py\", line 359, in export\n    __process()\n  File \"/usr/local/lib/python3.10/site-packages/mage_ai/io/sql.py\", line 292, in __process\n    table_exists = self.table_exists(schema_name, table_name)\n  File \"/usr/local/lib/python3.10/site-packages/mage_ai/io/postgres.py\", line 166, in table_exists\n    with self.conn.cursor() as cur:\n  File \"/usr/local/lib/python3.10/site-packages/mage_ai/io/base.py\", line 349, in conn\n    raise ConnectionError(\nConnectionError: No connection currently open. Open a new connection to access this property.\n"], "error_stack": [["  File \"/usr/local/bin/mage\", line 8, in <module>\n    sys.exit(app())\n", "  File \"/usr/local/lib/python3.10/site-packages/typer/main.py\", line 311, in __call__\n    return get_command(self)(*args, **kwargs)\n", "  File \"/usr/local/lib/python3.10/site-packages/click/core.py\", line 1130, in __call__\n    return self.main(*args, **kwargs)\n", "  File \"/usr/local/lib/python3.10/site-packages/typer/core.py\", line 778, in main\n    return _main(\n", "  File \"/usr/local/lib/python3.10/site-packages/typer/core.py\", line 216, in _main\n    rv = self.invoke(ctx)\n", "  File \"/usr/local/lib/python3.10/site-packages/click/core.py\", line 1657, in invoke\n    return _process_result(sub_ctx.command.invoke(sub_ctx))\n", "  File \"/usr/local/lib/python3.10/site-packages/click/core.py\", line 1404, in invoke\n    return ctx.invoke(self.callback, **ctx.params)\n", "  File \"/usr/local/lib/python3.10/site-packages/click/core.py\", line 760, in invoke\n    return __callback(*args, **kwargs)\n", "  File \"/usr/local/lib/python3.10/site-packages/typer/main.py\", line 683, in wrapper\n    return callback(**use_params)  # type: ignore\n", "  File \"/usr/local/lib/python3.10/site-packages/mage_ai/cli/main.py\", line 163, in start\n    start_server(\n", "  File \"/usr/local/lib/python3.10/site-packages/mage_ai/server/server.py\", line 659, in start_server\n    scheduler_manager.start_scheduler()\n", "  File \"/usr/local/lib/python3.10/site-packages/mage_ai/server/scheduler_manager.py\", line 87, in start_scheduler\n    proc.start()\n", "  File \"/usr/local/lib/python3.10/multiprocessing/process.py\", line 121, in start\n    self._popen = self._Popen(self)\n", "  File \"/usr/local/lib/python3.10/multiprocessing/context.py\", line 224, in _Popen\n    return _default_context.get_context().Process._Popen(process_obj)\n", "  File \"/usr/local/lib/python3.10/multiprocessing/context.py\", line 281, in _Popen\n    return Popen(process_obj)\n", "  File \"/usr/local/lib/python3.10/multiprocessing/popen_fork.py\", line 19, in __init__\n    self._launch(process_obj)\n", "  File \"/usr/local/lib/python3.10/multiprocessing/popen_fork.py\", line 71, in _launch\n    code = process_obj._bootstrap(parent_sentinel=child_r)\n", "  File \"/usr/local/lib/python3.10/multiprocessing/process.py\", line 314, in _bootstrap\n    self.run()\n", "  File \"/usr/local/lib/python3.10/multiprocessing/process.py\", line 108, in run\n    self._target(*self._args, **self._kwargs)\n", "  File \"/usr/local/lib/python3.10/site-packages/mage_ai/orchestration/db/process.py\", line 15, in start_session_and_run\n    results = target(*args)\n", "  File \"/usr/local/lib/python3.10/site-packages/mage_ai/server/scheduler_manager.py\", line 50, in run_scheduler\n    LoopTimeTrigger().start()\n", "  File \"/usr/local/lib/python3.10/site-packages/mage_ai/orchestration/triggers/loop_time_trigger.py\", line 14, in start\n    self.run()\n", "  File \"/usr/local/lib/python3.10/site-packages/mage_ai/orchestration/triggers/time_trigger.py\", line 11, in run\n    schedule_all()\n", "  File \"/usr/local/lib/python3.10/site-packages/mage_ai/orchestration/pipeline_scheduler_original.py\", line 1603, in schedule_all\n    PipelineScheduler(r).schedule()\n", "  File \"/usr/local/lib/python3.10/site-packages/mage_ai/orchestration/db/__init__.py\", line 149, in func_with_rollback\n    return func(*args, **kwargs)\n", "  File \"/usr/local/lib/python3.10/site-packages/mage_ai/orchestration/pipeline_scheduler_original.py\", line 319, in schedule\n    self.__schedule_blocks(block_runs)\n", "  File \"/usr/local/lib/python3.10/site-packages/mage_ai/orchestration/pipeline_scheduler_original.py\", line 584, in __schedule_blocks\n    job_manager.add_job(\n", "  File \"/usr/local/lib/python3.10/site-packages/mage_ai/orchestration/job_manager.py\", line 27, in add_job\n    self.queue.enqueue(job_id, target, *args, **kwargs)\n", "  File \"/usr/local/lib/python3.10/site-packages/mage_ai/orchestration/queue/process_queue.py\", line 108, in enqueue\n    self.start_worker_pool()\n", "  File \"/usr/local/lib/python3.10/site-packages/mage_ai/orchestration/queue/process_queue.py\", line 183, in start_worker_pool\n    self.worker_pool_proc.start()\n", "  File \"/usr/local/lib/python3.10/multiprocessing/process.py\", line 121, in start\n    self._popen = self._Popen(self)\n", "  File \"/usr/local/lib/python3.10/multiprocessing/context.py\", line 224, in _Popen\n    return _default_context.get_context().Process._Popen(process_obj)\n", "  File \"/usr/local/lib/python3.10/multiprocessing/context.py\", line 281, in _Popen\n    return Popen(process_obj)\n", "  File \"/usr/local/lib/python3.10/multiprocessing/popen_fork.py\", line 19, in __init__\n    self._launch(process_obj)\n", "  File \"/usr/local/lib/python3.10/multiprocessing/popen_fork.py\", line 71, in _launch\n    code = process_obj._bootstrap(parent_sentinel=child_r)\n", "  File \"/usr/local/lib/python3.10/multiprocessing/process.py\", line 314, in _bootstrap\n    self.run()\n", "  File \"/usr/local/lib/python3.10/multiprocessing/process.py\", line 108, in run\n    self._target(*self._args, **self._kwargs)\n", "  File \"/usr/local/lib/python3.10/site-packages/mage_ai/orchestration/queue/process_queue.py\", line 288, in poll_job_and_execute\n    worker.start()\n", "  File \"/usr/local/lib/python3.10/multiprocessing/process.py\", line 121, in start\n    self._popen = self._Popen(self)\n", "  File \"/usr/local/lib/python3.10/multiprocessing/context.py\", line 224, in _Popen\n    return _default_context.get_context().Process._Popen(process_obj)\n", "  File \"/usr/local/lib/python3.10/multiprocessing/context.py\", line 281, in _Popen\n    return Popen(process_obj)\n", "  File \"/usr/local/lib/python3.10/multiprocessing/popen_fork.py\", line 19, in __init__\n    self._launch(process_obj)\n", "  File \"/usr/local/lib/python3.10/multiprocessing/popen_fork.py\", line 71, in _launch\n    code = process_obj._bootstrap(parent_sentinel=child_r)\n", "  File \"/usr/local/lib/python3.10/multiprocessing/process.py\", line 314, in _bootstrap\n    self.run()\n", "  File \"/usr/local/lib/python3.10/site-packages/newrelic/api/background_task.py\", line 117, in wrapper\n    return wrapped(*args, **kwargs)\n", "  File \"/usr/local/lib/python3.10/site-packages/mage_ai/orchestration/queue/process_queue.py\", line 253, in run\n    start_session_and_run(args[1], *args[2], **args[3])\n", "  File \"/usr/local/lib/python3.10/site-packages/mage_ai/orchestration/db/process.py\", line 15, in start_session_and_run\n    results = target(*args)\n", "  File \"/usr/local/lib/python3.10/site-packages/mage_ai/orchestration/pipeline_scheduler_original.py\", line 1128, in run_block\n    return ExecutorFactory.get_block_executor(\n", "  File \"/usr/local/lib/python3.10/site-packages/mage_ai/data_preparation/executors/block_executor.py\", line 641, in execute\n    on_failure(\n", "  File \"/usr/local/lib/python3.10/site-packages/mage_ai/orchestration/db/__init__.py\", line 149, in func_with_rollback\n    return func(*args, **kwargs)\n", "  File \"/usr/local/lib/python3.10/site-packages/mage_ai/orchestration/pipeline_scheduler_original.py\", line 415, in on_block_failure\n    self.logger.exception(\n", "  File \"/usr/local/lib/python3.10/site-packages/mage_ai/data_preparation/logging/logger.py\", line 30, in exception\n    self.__send_message('exception', message, **kwargs)\n", "  File \"/usr/local/lib/python3.10/site-packages/mage_ai/data_preparation/logging/logger.py\", line 59, in __send_message\n    data['error_stack'] = traceback.format_stack(),\n"]], "error_stacktrace": ["No connection currently open. Open a new connection to access this property."]}
Traceback (most recent call last):
  File "/usr/local/lib/python3.10/site-packages/mage_ai/io/base.py", line 347, in conn
    return self._ctx
AttributeError: 'Postgres' object has no attribute '_ctx'

During handling of the above exception, another exception occurred:

Traceback (most recent call last):
  File "/usr/local/lib/python3.10/site-packages/mage_ai/data_preparation/executors/block_executor.py", line 613, in execute
    result = __execute_with_retry()
  File "/usr/local/lib/python3.10/site-packages/mage_ai/shared/retry.py", line 54, in retry_func
    raise e
  File "/usr/local/lib/python3.10/site-packages/mage_ai/shared/retry.py", line 38, in retry_func
    return func(*args, **kwargs)
  File "/usr/local/lib/python3.10/site-packages/mage_ai/data_preparation/executors/block_executor.py", line 588, in __execute_with_retry
    return self._execute(
  File "/usr/local/lib/python3.10/site-packages/mage_ai/data_preparation/executors/block_executor.py", line 1077, in _execute
    result = self.block.execute_sync(
  File "/usr/local/lib/python3.10/site-packages/mage_ai/data_preparation/models/block/__init__.py", line 1312, in execute_sync
    raise err
  File "/usr/local/lib/python3.10/site-packages/mage_ai/data_preparation/models/block/__init__.py", line 1221, in execute_sync
    output = self.execute_block(
  File "/usr/local/lib/python3.10/site-packages/mage_ai/data_preparation/models/block/__init__.py", line 1527, in execute_block
    outputs = self._execute_block(
  File "/usr/local/lib/python3.10/site-packages/mage_ai/data_preparation/models/block/__init__.py", line 1683, in _execute_block
    outputs = self.execute_block_function(
  File "/usr/local/lib/python3.10/site-packages/mage_ai/data_preparation/models/block/__init__.py", line 1722, in execute_block_function
    output = block_function_updated(*input_vars, **global_vars)
  File "<string>", line 25, in export_data_to_postgres
  File "/usr/local/lib/python3.10/site-packages/mage_ai/io/sql.py", line 359, in export
    __process()
  File "/usr/local/lib/python3.10/site-packages/mage_ai/io/sql.py", line 292, in __process
    table_exists = self.table_exists(schema_name, table_name)
  File "/usr/local/lib/python3.10/site-packages/mage_ai/io/postgres.py", line 166, in table_exists
    with self.conn.cursor() as cur:
  File "/usr/local/lib/python3.10/site-packages/mage_ai/io/base.py", line 349, in conn
    raise ConnectionError(
ConnectionError: No connection currently open. Open a new connection to access this property.
2024-02-09T00:00:32 {"block_run_id": 13, "block_uuid": "taxi_to_gcs_parquet", "pipeline_run_id": 2, "pipeline_schedule_id": 1, "pipeline_uuid": "green_taxi_etl", "hostname": "2156a6b6cd4d", "level": "INFO", "message": "BlockRun 13 (block_uuid: taxi_to_gcs_parquet) completes.", "timestamp": 1707436832.724219, "uuid": "2b15e6294bef434fb814128cdb3678cc"}
2024-02-09T00:00:34 {"block_run_id": 14, "block_uuid": "taxi_to_gcs_partitioned_parquet", "pipeline_run_id": 2, "pipeline_schedule_id": 1, "pipeline_uuid": "green_taxi_etl", "hostname": "2156a6b6cd4d", "level": "INFO", "message": "BlockRun 14 (block_uuid: taxi_to_gcs_partitioned_parquet) completes.", "timestamp": 1707436834.628932, "uuid": "d0bec7042bf643009f22438105c4a19c"}
2024-02-09T00:00:39 {"cpu": 2.36865234375, "cpu_total": 12, "cpu_usage": 0.1973876953125, "memory": 1226.0, "memory_total": 8864.0, "memory_usage": 0.13831227436823104, "pipeline_run_id": 2, "pipeline_schedule_id": 1, "pipeline_uuid": "green_taxi_etl", "hostname": "2156a6b6cd4d", "level": "INFO", "message": "Pipeline green_taxi_etl for run 2 in schedule 1 is alive.", "timestamp": 1707436839.127638, "uuid": "e28cc83fb42047a3aaf6c177424667c1"}
